<?xml version="1.0"?>
<sdf version="1.9">
  <model name="iiwa7">
    <link name="iiwa_link_0">
      <visual name="base_visual">
        <geometry>
          <cylinder>
            <radius>0.1</radius>
            <length>0.2</length>
          </cylinder>
        </geometry>
        <material>
          <diffuse>0.3 0.3 0.3 1.0</diffuse>
        </material>
      </visual>
      <pose>0 0 0.1 0 0 0</pose>
    </link>
    
    <link name="iiwa_link_1">
      <visual name="link1_visual">
        <geometry>
          <box>
            <size>0.1 0.1 0.3</size>
          </box>
        </geometry>
        <material>
          <diffuse>0.8 0.2 0.2 1.0</diffuse>
        </material>
      </visual>
      <pose>0 0 0.25 0 0 0</pose>
    </link>
    
    <joint name="iiwa_joint_1" type="revolute">
      <parent>iiwa_link_0</parent>
      <child>iiwa_link_1</child>
      <axis>
        <xyz>0 0 1</xyz>
      </axis>
    </joint>
    
    <!-- Add more links and joints for a 7-DOF arm -->
    <link name="iiwa_link_2">
      <visual name="link2_visual">
        <geometry>
          <box>
            <size>0.08 0.08 0.25</size>
          </box>
        </geometry>
        <material>
          <diffuse>0.2 0.8 0.2 1.0</diffuse>
        </material>
      </visual>
      <pose>0 0 0.125 0 0 0</pose>
    </link>
    
    <joint name="iiwa_joint_2" type="revolute">
      <parent>iiwa_link_1</parent>
      <child>iiwa_link_2</child>
      <axis>
        <xyz>0 1 0</xyz>
      </axis>
    </joint>
    
    <!-- Continue with links 3-7 for a full 7-DOF arm -->
    <link name="iiwa_link_3">
      <visual name="link3_visual">
        <geometry>
          <box>
            <size>0.07 0.07 0.2</size>
          </box>
        </geometry>
        <material>
          <diffuse>0.2 0.2 0.8 1.0</diffuse>
        </material>
      </visual>
      <pose>0 0 0.1 0 0 0</pose>
    </link>
    
    <joint name="iiwa_joint_3" type="revolute">
      <parent>iiwa_link_2</parent>
      <child>iiwa_link_3</child>
      <axis>
        <xyz>0 1 0</xyz>
      </axis>
    </joint>
    
    <link name="iiwa_link_4">
      <visual name="link4_visual">
        <geometry>
          <box>
            <size>0.06 0.06 0.15</size>
          </box>
        </geometry>
        <material>
          <diffuse>0.8 0.8 0.2 1.0</diffuse>
        </material>
      </visual>
      <pose>0 0 0.075 0 0 0</pose>
    </link>
    
    <joint name="iiwa_joint_4" type="revolute">
      <parent>iiwa_link_3</parent>
      <child>iiwa_link_4</child>
      <axis>
        <xyz>0 0 1</xyz>
      </axis>
    </joint>
    
    <link name="iiwa_link_5">
      <visual name="link5_visual">
        <geometry>
          <box>
            <size>0.05 0.05 0.12</size>
          </box>
        </geometry>
        <material>
          <diffuse>0.8 0.2 0.8 1.0</diffuse>
        </material>
      </visual>
      <pose>0 0 0.06 0 0 0</pose>
    </link>
    
    <joint name="iiwa_joint_5" type="revolute">
      <parent>iiwa_link_4</parent>
      <child>iiwa_link_5</child>
      <axis>
        <xyz>0 1 0</xyz>
      </axis>
    </joint>
    
    <link name="iiwa_link_6">
      <visual name="link6_visual">
        <geometry>
          <box>
            <size>0.04 0.04 0.1</size>
          </box>
        </geometry>
        <material>
          <diffuse>0.2 0.8 0.8 1.0</diffuse>
        </material>
      </visual>
      <pose>0 0 0.05 0 0 0</pose>
    </link>
    
    <joint name="iiwa_joint_6" type="revolute">
      <parent>iiwa_link_5</parent>
      <child>iiwa_link_6</child>
      <axis>
        <xyz>0 0 1</xyz>
      </axis>
    </joint>
    
    <link name="iiwa_link_7">
      <visual name="link7_visual">
        <geometry>
          <box>
            <size>0.03 0.03 0.08</size>
          </box>
        </geometry>
        <material>
          <diffuse>0.5 0.5 0.5 1.0</diffuse>
        </material>
      </visual>
      <pose>0 0 0.04 0 0 0</pose>
    </link>
    
    <joint name="iiwa_joint_7" type="revolute">
      <parent>iiwa_link_6</parent>
      <child>iiwa_link_7</child>
      <axis>
        <xyz>0 1 0</xyz>
      </axis>
    </joint>
  </model>
</sdf>